<?xml version="1.0"?>
<robot xmlns:xacro="http://www.ros.org/wiki/xacro" name="goliath">

  <xacro:property name="coxa_length" value="0.022" />
  <xacro:property name="femur_length" value="0.08" />
  <xacro:property name="tibia_length" value="0.115" />
  <xacro:property name="leg_base_angle" value="${34.4/180*pi}" />


  <xacro:property name="legs_joint_effort" value="6.0"/>
  <xacro:property name="legs_joint_velocity" value="0.524"/>

  <material name="alumunium">
    <color rgba="0.9 0.9 0.9 1"/>
  </material>

  <material name="rubber">
    <color rgba="0 0 0 1"/>
  </material>

 <!-- Body -->
  <link name="body_link">
    <visual>
      <geometry>
        <mesh filename="package://goliath_description/meshes/body.stl" scale= "0.001 0.001 0.001" />
      </geometry>
      <origin xyz="0.0 0.0 0.0448" rpy="0 0 0"/>
      <material name="alumunium"/>
    </visual>
  </link>

<!-- Leg macro -->
  <xacro:macro name="leg" params="side location x y angle">

    <link name="${side}${location}_coxa_link">
      <visual>
        <geometry>
          <mesh filename="package://goliath_description/meshes/${side}_coxa.stl" scale= "0.001 0.001 0.001" />
        </geometry>
        <origin xyz="0.0 0.0 0.0433" rpy="0 0 0"/>
        <material name="alumunium"/>
      </visual>
    </link>

    <joint name="${side}${location}_coxa_joint" type="revolute">
      <parent link="body_link"/>
      <child link="${side}${location}_coxa_link"/>
      <origin xyz="${x} ${y} 0.00" rpy="0 0 ${angle}"/>
      <limit effort="${legs_joint_effort}" velocity="${legs_joint_velocity}" lower="-3.14" upper="3.14"/>
      <axis xyz="0 0 1"/>
    </joint>

    <link name="${side}${location}_femur_link">
      <visual>
        <geometry>
          <mesh filename="package://goliath_description/meshes/${side}_femur.stl" scale= "0.001 0.001 0.001" />
        </geometry>
        <origin xyz="0 0 0.0" rpy="0.0 0 0"/>
        <material name="alumunium"/>
      </visual>
    </link>

    <joint name="${side}${location}_femur_joint" type="revolute">
      <parent link="${side}${location}_coxa_link"/>
      <child link="${side}${location}_femur_link"/>
      <origin xyz="${coxa_length} 0.00 0.00" rpy="0 -0.785 0.0"/>
      <limit effort="${legs_joint_effort}" velocity="${legs_joint_velocity}" lower="-3.14" upper="3.14"/>
      <axis xyz="0 1 0"/>
    </joint>

    <link name="${side}${location}_tibia_link">
      <visual>
        <geometry>
           <mesh filename="package://goliath_description/meshes/${side}_tibia.stl" scale= "0.001 0.001 0.001" />
        </geometry>
        <origin xyz="0.0 0 0.0" rpy="0 0 0"/>
        <material name="alumunium"/>
      </visual>
    </link>

    <joint name="${side}${location}_tibia_joint" type="revolute">
      <parent link="${side}${location}_femur_link"/>
      <child link="${side}${location}_tibia_link"/>
      <origin xyz="${femur_length} 0.0 0.0" rpy="0 -0.785 0"/>
      <limit effort="${legs_joint_effort}" velocity="${legs_joint_velocity}" lower="-3.14" upper="3.14"/>
      <axis xyz="0 1 0"/>
    </joint>

    <link name="${side}${location}_tarsus_link">
      <visual>
        <geometry>
           <mesh filename="package://goliath_description/meshes/leg_end.stl" scale= "0.001 0.001 0.001" />
        </geometry>
        <origin xyz="0.0 0.0 0.0" rpy="0 0.25 0"/>
        <material name="rubber"/>
      </visual>
    </link>

    <joint name="${side}${location}_tarsus_joint" type="fixed">
      <parent link="${side}${location}_tibia_link"/>
      <child link="${side}${location}_tarsus_link"/>
      <origin xyz="-${tibia_length} 0.0 0"/>
    </joint>

  </xacro:macro>

  <xacro:leg side="l" location="f" x="-0.063" y="0.092"  angle="${pi - leg_base_angle}" />
  <xacro:leg side="l" location="m" x="-0.072" y="0"      angle="${pi}" />
  <xacro:leg side="l" location="r" x="-0.063" y="-0.092" angle="${-(pi - leg_base_angle)}" />

  <xacro:leg side="r" location="f" x="0.063"  y="0.092"  angle="${leg_base_angle}" />
  <xacro:leg side="r" location="m" x="0.072"  y="0"      angle="${0}" />
  <xacro:leg side="r" location="r" x="0.063"  y="-0.092" angle="-${leg_base_angle}" />

</robot>
