<?xml version="1.0"?>
<robot name="goliath">

  <material name="alumunium">
    <color rgba="0.9 0.9 0.9 1"/>
  </material>

  <material name="rubber">
    <color rgba="0 0 0 1"/>
  </material>

 <link name="body_link">
    <visual>
      <geometry>
      <mesh filename="package://goliath_description/meshes/body.stl" scale= "0.001 0.001 0.001" />
      </geometry>
      <origin xyz="0.0 0.0 0.0448" rpy="0 0 0"/>
      <material name="alumunium"/>
    </visual>
  </link>

<link name="lf_coxa_link">
  <visual>
    <geometry>
    <mesh filename="package://goliath_description/meshes/l_coxa.stl" scale= "0.001 0.001 0.001" />
    </geometry>
    <origin xyz="0.0 0.0 0.0433" rpy="0 0 0"/>
    <material name="alumunium"/>
  </visual>
</link>

<joint name="lf_coxa_joint" type="revolute">
  <parent link="body_link"/>
  <child link="lf_coxa_link"/>
  <origin xyz="-0.063 0.092 0.00" rpy="0 0 2.17"/>
  <limit effort="1.0" velocity="1.0" lower="-3.14" upper="3.14"/>
  <axis xyz="0 0 1"/>
</joint>

<link name="lf_femur_link">
  <visual>
    <geometry>
      <mesh filename="package://goliath_description/meshes/l_femur.stl" scale= "0.001 0.001 0.001" />
    </geometry>
    <origin xyz="0 0 0.0" rpy="0.0 0 0"/>
    <material name="alumunium"/>
  </visual>
</link>

<joint name="lf_femur_joint" type="revolute">
  <parent link="lf_coxa_link"/>
  <child link="lf_femur_link"/>
  <origin xyz="0.022 0.00 0.00" rpy="0 -0.785 0.0"/>
  <limit effort="1.0" velocity="1.0" lower="-3.14" upper="3.14"/>
  <axis xyz="0 1 0"/>
</joint>

<link name="lf_tibia_link">
  <visual>
    <geometry>
       <mesh filename="package://goliath_description/meshes/l_tibia.stl" scale= "0.001 0.001 0.001" />
    </geometry>
    <origin xyz="0.0 0 0.0" rpy="0 0 0"/>
    <material name="alumunium"/>
  </visual>
</link>

<joint name="lf_tibia_joint" type="revolute">
  <parent link="lf_femur_link"/>
  <child link="lf_tibia_link"/>
  <origin xyz="0.08 0.0 0.0" rpy="0 -0.785 0"/>
  <limit effort="1.0" velocity="1.0" lower="-3.14" upper="3.14"/>
  <axis xyz="0 1 0"/>
</joint>

<link name="lf_tarsus_link">
  <visual>
    <geometry>
       <mesh filename="package://goliath_description/meshes/leg_end.stl" scale= "0.001 0.001 0.001" />
    </geometry>
    <origin xyz="0.0 0.0 0.0" rpy="0 0.25 0"/>
    <material name="rubber"/>
  </visual>
</link>

<joint name="lf_tarsus_joint" type="fixed">
  <parent link="lf_tibia_link"/>
  <child link="lf_tarsus_link"/>
  <origin xyz="-0.115 0.0 0"/>
</joint>

<!-- Left medium leg -->

<link name="lm_coxa_link">
  <visual>
    <geometry>
    <mesh filename="package://goliath_description/meshes/l_coxa.stl" scale= "0.001 0.001 0.001" />
    </geometry>
    <origin xyz="0.0 0.0 0.0433" rpy="0 0 0"/>
    <material name="alumunium"/>
  </visual>
</link>

<joint name="lm_coxa_joint" type="revolute">
  <parent link="body_link"/>
  <child link="lm_coxa_link"/>
  <origin xyz="-0.072 0.0 0.0" rpy="0 0 3.14"/>
  <limit effort="1.0" velocity="1.0" lower="-3.14" upper="3.14"/>
  <axis xyz="0 0 1"/>
</joint>

<link name="lm_femur_link">
  <visual>
    <geometry>
      <mesh filename="package://goliath_description/meshes/l_femur.stl" scale= "0.001 0.001 0.001" />
    </geometry>
    <origin xyz="0 0 0.0" rpy="0.0 0 0"/>
    <material name="alumunium"/>
  </visual>
</link>

<joint name="lm_femur_joint" type="revolute">
  <parent link="lm_coxa_link"/>
  <child link="lm_femur_link"/>
  <origin xyz="0.022 0.00 0.00" rpy="0 -0.785 0.0"/>
  <limit effort="1.0" velocity="1.0" lower="-3.14" upper="3.14"/>
  <axis xyz="0 1 0"/>
</joint>

<link name="lm_tibia_link">
  <visual>
    <geometry>
       <mesh filename="package://goliath_description/meshes/l_tibia.stl" scale= "0.001 0.001 0.001" />
    </geometry>
    <origin xyz="0.0 0 0.0" rpy="0 0 0"/>
    <material name="alumunium"/>
  </visual>
</link>

<joint name="lm_tibia_joint" type="revolute">
  <parent link="lm_femur_link"/>
  <child link="lm_tibia_link"/>
  <origin xyz="0.08 0.0 0.0" rpy="0 -0.785 0"/>
  <limit effort="1.0" velocity="1.0" lower="-3.14" upper="3.14"/>
  <axis xyz="0 1 0"/>
</joint>

<link name="lm_tarsus_link">
  <visual>
    <geometry>
       <mesh filename="package://goliath_description/meshes/leg_end.stl" scale= "0.001 0.001 0.001" />
    </geometry>
    <origin xyz="0.0 0.0 0.0" rpy="0 0.25 0"/>
    <material name="rubber"/>
  </visual>
</link>

<joint name="lm_tarsus_joint" type="fixed">
  <parent link="lm_tibia_link"/>
  <child link="lm_tarsus_link"/>
  <origin xyz="-0.115 0.0 0"/>
</joint>

<!-- Left rear leg -->

<link name="lr_coxa_link">
  <visual>
    <geometry>
    <mesh filename="package://goliath_description/meshes/l_coxa.stl" scale= "0.001 0.001 0.001" />
    </geometry>
    <origin xyz="0.0 0.0 0.0433" rpy="0 0 0"/>
    <material name="alumunium"/>
  </visual>
</link>

<joint name="lr_coxa_joint" type="revolute">
  <parent link="body_link"/>
  <child link="lr_coxa_link"/>
  <origin xyz="-0.063 -0.092 0.00" rpy="0 0 -2.17"/>
  <limit effort="1.0" velocity="1.0" lower="-3.14" upper="3.14"/>
  <axis xyz="0 0 1"/>
</joint>

<link name="lr_femur_link">
  <visual>
    <geometry>
      <mesh filename="package://goliath_description/meshes/l_femur.stl" scale= "0.001 0.001 0.001" />
    </geometry>
    <origin xyz="0 0 0.0" rpy="0 0 0"/>
    <material name="alumunium"/>
  </visual>
</link>

<joint name="lr_femur_joint" type="revolute">
  <parent link="lr_coxa_link"/>
  <child link="lr_femur_link"/>
  <origin xyz="0.022 0.00 0.00" rpy="0 -0.785 0.0"/>
  <limit effort="1.0" velocity="1.0" lower="-3.14" upper="3.14"/>
  <axis xyz="0 1 0"/>
</joint>

<link name="lr_tibia_link">
  <visual>
    <geometry>
       <mesh filename="package://goliath_description/meshes/l_tibia.stl" scale= "0.001 0.001 0.001" />
    </geometry>
    <origin xyz="0.0 0 0.0" rpy="0 0 0"/>
    <material name="alumunium"/>
  </visual>
</link>

<joint name="lr_tibia_joint" type="revolute">
  <parent link="lr_femur_link"/>
  <child link="lr_tibia_link"/>
  <origin xyz="0.08 0.0 0.0" rpy="0 -0.785 0"/>
  <limit effort="1.0" velocity="1.0" lower="-3.14" upper="3.14"/>
  <axis xyz="0 1 0"/>
</joint>

<link name="lr_tarsus_link">
  <visual>
    <geometry>
       <mesh filename="package://goliath_description/meshes/leg_end.stl" scale= "0.001 0.001 0.001" />
    </geometry>
    <origin xyz="0.0 0.0 0.0" rpy="0 0.25 0"/>
    <material name="rubber"/>
  </visual>
</link>

<joint name="lr_tarsus_joint" type="fixed">
  <parent link="lr_tibia_link"/>
  <child link="lr_tarsus_link"/>
  <origin xyz="-0.115 0.0 0"/>
</joint>

<!-- Right front leg -->

<link name="rf_coxa_link">
  <visual>
    <geometry>
    <mesh filename="package://goliath_description/meshes/r_coxa.stl" scale= "0.001 0.001 0.001" />
    </geometry>
    <origin xyz="0.0 0.0 0.0433" rpy="0 0 0"/>
    <material name="alumunium"/>
  </visual>
</link>

<joint name="rf_coxa_joint" type="revolute">
  <parent link="body_link"/>
  <child link="rf_coxa_link"/>
  <origin xyz="0.063 0.092 0.00" rpy="0 0 0.6"/>
  <limit effort="1.0" velocity="1.0" lower="-3.14" upper="3.14"/>
  <axis xyz="0 0 1"/>
</joint>

<link name="rf_femur_link">
  <visual>
    <geometry>
      <mesh filename="package://goliath_description/meshes/r_femur.stl" scale= "0.001 0.001 0.001" />
    </geometry>
    <origin xyz="0 0 0.0" rpy="0 0 0"/>
    <material name="alumunium"/>
  </visual>
</link>

<joint name="rf_femur_joint" type="revolute">
  <parent link="rf_coxa_link"/>
  <child link="rf_femur_link"/>
  <origin xyz="0.022 0.00 0.00" rpy="0 -0.785 0.0"/>
  <limit effort="1.0" velocity="1.0" lower="-3.14" upper="3.14"/>
  <axis xyz="0 1 0"/>
</joint>

<link name="rf_tibia_link">
  <visual>
    <geometry>
       <mesh filename="package://goliath_description/meshes/r_tibia.stl" scale= "0.001 0.001 0.001" />
    </geometry>
    <origin xyz="0.0 0 0.0" rpy="0 0 0"/>
    <material name="alumunium"/>
  </visual>
</link>

<joint name="rf_tibia_joint" type="revolute">
  <parent link="rf_femur_link"/>
  <child link="rf_tibia_link"/>
  <origin xyz="0.08 0.0 0.0" rpy="0 -0.785 0"/>
  <limit effort="1.0" velocity="1.0" lower="-3.14" upper="3.14"/>
  <axis xyz="0 1 0"/>
</joint>

<link name="rf_tarsus_link">
  <visual>
    <geometry>
       <mesh filename="package://goliath_description/meshes/leg_end.stl" scale= "0.001 0.001 0.001" />
    </geometry>
    <origin xyz="0.0 0.0 0.0" rpy="0 0.25 0"/>
    <material name="rubber"/>
  </visual>
</link>

<joint name="rf_tarsus_joint" type="fixed">
  <parent link="rf_tibia_link"/>
  <child link="rf_tarsus_link"/>
  <origin xyz="-0.115 0.0 0"/>
</joint>
<!-- Right medium leg -->

<link name="rm_coxa_link">
  <visual>
    <geometry>
    <mesh filename="package://goliath_description/meshes/r_coxa.stl" scale= "0.001 0.001 0.001" />
    </geometry>
    <origin xyz="0.0 0.0 0.0433" rpy="0 0 0"/>
    <material name="alumunium"/>
  </visual>
</link>

<joint name="rm_coxa_joint" type="revolute">
  <parent link="body_link"/>
  <child link="rm_coxa_link"/>
  <origin xyz="0.072 0 0.00" rpy="0 0 0"/>
  <limit effort="1.0" velocity="1.0" lower="-3.14" upper="3.14"/>
  <axis xyz="0 0 1"/>
</joint>

<link name="rm_femur_link">
  <visual>
    <geometry>
      <mesh filename="package://goliath_description/meshes/r_femur.stl" scale= "0.001 0.001 0.001" />
    </geometry>
    <origin xyz="0 0 0.0" rpy="0 0 0"/>
    <material name="alumunium"/>
  </visual>
</link>

<joint name="rm_femur_joint" type="revolute">
  <parent link="rm_coxa_link"/>
  <child link="rm_femur_link"/>
  <origin xyz="0.022 0.00 0.00" rpy="0 -0.785 0.0"/>
  <limit effort="1.0" velocity="1.0" lower="-3.14" upper="3.14"/>
  <axis xyz="0 1 0"/>
</joint>

<link name="rm_tibia_link">
  <visual>
    <geometry>
       <mesh filename="package://goliath_description/meshes/r_tibia.stl" scale= "0.001 0.001 0.001" />
    </geometry>
    <origin xyz="0.0 0 0.0" rpy="0 0 0"/>
    <material name="alumunium"/>
  </visual>
</link>

<joint name="rm_tibia_joint" type="revolute">
  <parent link="rm_femur_link"/>
  <child link="rm_tibia_link"/>
  <origin xyz="0.08 0.0 0.0" rpy="0 -0.785 0"/>
  <limit effort="1.0" velocity="1.0" lower="-3.14" upper="3.14"/>
  <axis xyz="0 1 0"/>
</joint>

<link name="rm_tarsus_link">
  <visual>
    <geometry>
       <mesh filename="package://goliath_description/meshes/leg_end.stl" scale= "0.001 0.001 0.001" />
    </geometry>
    <origin xyz="0.0 0.0 0.0" rpy="0 0.25 0"/>
    <material name="rubber"/>
  </visual>
</link>

<joint name="rm_tarsus_joint" type="fixed">
  <parent link="rm_tibia_link"/>
  <child link="rm_tarsus_link"/>
  <origin xyz="-0.115 0.0 0"/>
</joint>

<!-- Right rear leg -->

<link name="rr_coxa_link">
  <visual>
    <geometry>
    <mesh filename="package://goliath_description/meshes/r_coxa.stl" scale= "0.001 0.001 0.001" />
    </geometry>
    <origin xyz="0.0 0.0 0.0433" rpy="0 0 0"/>
    <material name="alumunium"/>
  </visual>
</link>

<joint name="rr_coxa_joint" type="revolute">
  <parent link="body_link"/>
  <child link="rr_coxa_link"/>
  <origin xyz="0.063 -0.092 0.00" rpy="0 0 -0.6"/>
  <limit effort="1.0" velocity="1.0" lower="-3.14" upper="3.14"/>
  <axis xyz="0 0 1"/>
</joint>

<link name="rr_femur_link">
  <visual>
    <geometry>
      <mesh filename="package://goliath_description/meshes/r_femur.stl" scale= "0.001 0.001 0.001" />
    </geometry>
    <origin xyz="0 0 0.0" rpy="0 0 0"/>
    <material name="alumunium"/>
  </visual>
</link>

<joint name="rr_femur_joint" type="revolute">
  <parent link="rr_coxa_link"/>
  <child link="rr_femur_link"/>
  <origin xyz="0.022 0.00 0.00" rpy="0 -0.785 0.0"/>
  <limit effort="1.0" velocity="1.0" lower="-3.14" upper="3.14"/>
  <axis xyz="0 1 0"/>
</joint>

<link name="rr_tibia_link">
  <visual>
    <geometry>
       <mesh filename="package://goliath_description/meshes/r_tibia.stl" scale= "0.001 0.001 0.001" />
    </geometry>
    <origin xyz="0.0 0 0.0" rpy="0 0 0"/>
    <material name="alumunium"/>
  </visual>
</link>

<joint name="rr_tibia_joint" type="revolute">
  <parent link="rr_femur_link"/>
  <child link="rr_tibia_link"/>
  <origin xyz="0.08 0.0 0.0" rpy="0 -0.785 0"/>
  <limit effort="1.0" velocity="1.0" lower="-3.14" upper="3.14"/>
  <axis xyz="0 1 0"/>
</joint>

<link name="rr_tarsus_link">
  <visual>
    <geometry>
       <mesh filename="package://goliath_description/meshes/leg_end.stl" scale= "0.001 0.001 0.001" />
    </geometry>
    <origin xyz="0.0 0.0 0.0" rpy="0 0.25 0"/>
    <material name="rubber"/>
  </visual>
</link>

<joint name="rr_tarsus_joint" type="fixed">
  <parent link="rr_tibia_link"/>
  <child link="rr_tarsus_link"/>
  <origin xyz="-0.115 0.0 0"/>
</joint>

</robot>
